---STARTING---
training | samples: 1.0, clients: 6
Run 0
Using downloaded and verified file: /common/home/rp1110/.medmnist/breastmnist.npz
Using downloaded and verified file: /common/home/rp1110/.medmnist/breastmnist.npz
Run 1
Using downloaded and verified file: /common/home/rp1110/.medmnist/breastmnist.npz
Using downloaded and verified file: /common/home/rp1110/.medmnist/breastmnist.npz
Exception ignored in: <Finalize object, dead>
Traceback (most recent call last):
  File "/common/system/anaconda/envs/python38/lib/python3.8/multiprocessing/util.py", line 224, in __call__
    res = self._callback(*self._args, **self._kwargs)
  File "/common/system/anaconda/envs/python38/lib/python3.8/multiprocessing/synchronize.py", line 87, in _cleanup
    sem_unlink(name)
FileNotFoundError: [Errno 2] No such file or directory
Exception ignored in: <Finalize object, dead>
Traceback (most recent call last):
  File "/common/system/anaconda/envs/python38/lib/python3.8/multiprocessing/util.py", line 224, in __call__
    res = self._callback(*self._args, **self._kwargs)
  File "/common/system/anaconda/envs/python38/lib/python3.8/multiprocessing/synchronize.py", line 87, in _cleanup
    sem_unlink(name)
FileNotFoundError: [Errno 2] No such file or directory
Exception ignored in: <Finalize object, dead>
Traceback (most recent call last):
  File "/common/system/anaconda/envs/python38/lib/python3.8/multiprocessing/util.py", line 224, in __call__
    res = self._callback(*self._args, **self._kwargs)
  File "/common/system/anaconda/envs/python38/lib/python3.8/multiprocessing/synchronize.py", line 87, in _cleanup
    sem_unlink(name)
FileNotFoundError: [Errno 2] No such file or directory
Exception ignored in: <Finalize object, dead>
Traceback (most recent call last):
  File "/common/system/anaconda/envs/python38/lib/python3.8/multiprocessing/util.py", line 224, in __call__
    res = self._callback(*self._args, **self._kwargs)
  File "/common/system/anaconda/envs/python38/lib/python3.8/multiprocessing/synchronize.py", line 87, in _cleanup
    sem_unlink(name)
FileNotFoundError: [Errno 2] No such file or directory
Exception ignored in: <Finalize object, dead>
Traceback (most recent call last):
  File "/common/system/anaconda/envs/python38/lib/python3.8/multiprocessing/util.py", line 224, in __call__
    res = self._callback(*self._args, **self._kwargs)
  File "/common/system/anaconda/envs/python38/lib/python3.8/multiprocessing/synchronize.py", line 87, in _cleanup
    sem_unlink(name)
FileNotFoundError: [Errno 2] No such file or directory
Exception ignored in: <Finalize object, dead>
Traceback (most recent call last):
  File "/common/system/anaconda/envs/python38/lib/python3.8/multiprocessing/util.py", line 224, in __call__
    res = self._callback(*self._args, **self._kwargs)
  File "/common/system/anaconda/envs/python38/lib/python3.8/multiprocessing/synchronize.py", line 87, in _cleanup
    sem_unlink(name)
FileNotFoundError: [Errno 2] No such file or directory
Saving to ../data/breast_final/local_100_6
Saving to ../data/breast_final/centralized_100_6
Saving to ../data/breast_final/step_100_6
Saving to ../data/breast_final/factors_core_100_6
Saving to ../data/breast_final/one_iter_100_6
Saving to ../data/breast_final/five_iter_100_6
FINISHED PERCENT 100.0 CLIENTS 6
/common/system/anaconda/envs/python38/lib/python3.8/multiprocessing/resource_tracker.py:216: UserWarning: resource_tracker: There appear to be 6 leaked semaphore objects to clean up at shutdown
  warnings.warn('resource_tracker: There appear to be %d '
/common/system/anaconda/envs/python38/lib/python3.8/multiprocessing/resource_tracker.py:229: UserWarning: resource_tracker: '/loky-3124169-ofsgxrxt': [Errno 2] No such file or directory
  warnings.warn('resource_tracker: %r: %s' % (name, e))
/common/system/anaconda/envs/python38/lib/python3.8/multiprocessing/resource_tracker.py:229: UserWarning: resource_tracker: '/loky-3124169-b07bmj0t': [Errno 2] No such file or directory
  warnings.warn('resource_tracker: %r: %s' % (name, e))
/common/system/anaconda/envs/python38/lib/python3.8/multiprocessing/resource_tracker.py:229: UserWarning: resource_tracker: '/loky-3124169-jn6t7wkt': [Errno 2] No such file or directory
  warnings.warn('resource_tracker: %r: %s' % (name, e))
/common/system/anaconda/envs/python38/lib/python3.8/multiprocessing/resource_tracker.py:229: UserWarning: resource_tracker: '/loky-3124169-iwgpi9_2': [Errno 2] No such file or directory
  warnings.warn('resource_tracker: %r: %s' % (name, e))
/common/system/anaconda/envs/python38/lib/python3.8/multiprocessing/resource_tracker.py:229: UserWarning: resource_tracker: '/loky-3124169-91qw0vi_': [Errno 2] No such file or directory
  warnings.warn('resource_tracker: %r: %s' % (name, e))
/common/system/anaconda/envs/python38/lib/python3.8/multiprocessing/resource_tracker.py:229: UserWarning: resource_tracker: '/loky-3124169-vyx5e5qv': [Errno 2] No such file or directory
  warnings.warn('resource_tracker: %r: %s' % (name, e))
