---STARTING---
training | samples: 1.0, clients: 6
Run 0
Using downloaded and verified file: /common/home/rp1110/.medmnist/vesselmnist3d.npz
Using downloaded and verified file: /common/home/rp1110/.medmnist/vesselmnist3d.npz
Run 1
Using downloaded and verified file: /common/home/rp1110/.medmnist/vesselmnist3d.npz
Using downloaded and verified file: /common/home/rp1110/.medmnist/vesselmnist3d.npz
Exception ignored in: <Finalize object, dead>
Traceback (most recent call last):
  File "/common/system/anaconda/envs/python38/lib/python3.8/multiprocessing/util.py", line 224, in __call__
    res = self._callback(*self._args, **self._kwargs)
  File "/common/system/anaconda/envs/python38/lib/python3.8/multiprocessing/synchronize.py", line 87, in _cleanup
    sem_unlink(name)
FileNotFoundError: [Errno 2] No such file or directory
Exception ignored in: <Finalize object, dead>
Traceback (most recent call last):
  File "/common/system/anaconda/envs/python38/lib/python3.8/multiprocessing/util.py", line 224, in __call__
    res = self._callback(*self._args, **self._kwargs)
  File "/common/system/anaconda/envs/python38/lib/python3.8/multiprocessing/synchronize.py", line 87, in _cleanup
    sem_unlink(name)
FileNotFoundError: [Errno 2] No such file or directory
Exception ignored in: <Finalize object, dead>
Traceback (most recent call last):
  File "/common/system/anaconda/envs/python38/lib/python3.8/multiprocessing/util.py", line 224, in __call__
    res = self._callback(*self._args, **self._kwargs)
  File "/common/system/anaconda/envs/python38/lib/python3.8/multiprocessing/synchronize.py", line 87, in _cleanup
    sem_unlink(name)
FileNotFoundError: [Errno 2] No such file or directory
Exception ignored in: <Finalize object, dead>
Traceback (most recent call last):
  File "/common/system/anaconda/envs/python38/lib/python3.8/multiprocessing/util.py", line 224, in __call__
    res = self._callback(*self._args, **self._kwargs)
  File "/common/system/anaconda/envs/python38/lib/python3.8/multiprocessing/synchronize.py", line 87, in _cleanup
    sem_unlink(name)
FileNotFoundError: [Errno 2] No such file or directory
Exception ignored in: <Finalize object, dead>
Traceback (most recent call last):
  File "/common/system/anaconda/envs/python38/lib/python3.8/multiprocessing/util.py", line 224, in __call__
    res = self._callback(*self._args, **self._kwargs)
  File "/common/system/anaconda/envs/python38/lib/python3.8/multiprocessing/synchronize.py", line 87, in _cleanup
    sem_unlink(name)
FileNotFoundError: [Errno 2] No such file or directory
Exception ignored in: <Finalize object, dead>
Traceback (most recent call last):
  File "/common/system/anaconda/envs/python38/lib/python3.8/multiprocessing/util.py", line 224, in __call__
    res = self._callback(*self._args, **self._kwargs)
  File "/common/system/anaconda/envs/python38/lib/python3.8/multiprocessing/synchronize.py", line 87, in _cleanup
    sem_unlink(name)
FileNotFoundError: [Errno 2] No such file or directory
Run 2
Using downloaded and verified file: /common/home/rp1110/.medmnist/vesselmnist3d.npz
Using downloaded and verified file: /common/home/rp1110/.medmnist/vesselmnist3d.npz
Run 3
Using downloaded and verified file: /common/home/rp1110/.medmnist/vesselmnist3d.npz
Using downloaded and verified file: /common/home/rp1110/.medmnist/vesselmnist3d.npz
Saving to ../data/vessel_final_2/local_100_6
Saving to ../data/vessel_final_2/centralized_100_6
Saving to ../data/vessel_final_2/step_100_6
Saving to ../data/vessel_final_2/factors_core_100_6
Saving to ../data/vessel_final_2/one_iter_100_6
Saving to ../data/vessel_final_2/five_iter_100_6
FINISHED PERCENT 100.0 CLIENTS 6
/common/system/anaconda/envs/python38/lib/python3.8/multiprocessing/resource_tracker.py:216: UserWarning: resource_tracker: There appear to be 6 leaked semaphore objects to clean up at shutdown
  warnings.warn('resource_tracker: There appear to be %d '
/common/system/anaconda/envs/python38/lib/python3.8/multiprocessing/resource_tracker.py:229: UserWarning: resource_tracker: '/loky-3651192-1avinp1o': [Errno 2] No such file or directory
  warnings.warn('resource_tracker: %r: %s' % (name, e))
/common/system/anaconda/envs/python38/lib/python3.8/multiprocessing/resource_tracker.py:229: UserWarning: resource_tracker: '/loky-3651192-dmhwjiaw': [Errno 2] No such file or directory
  warnings.warn('resource_tracker: %r: %s' % (name, e))
/common/system/anaconda/envs/python38/lib/python3.8/multiprocessing/resource_tracker.py:229: UserWarning: resource_tracker: '/loky-3651192-xo8idrsi': [Errno 2] No such file or directory
  warnings.warn('resource_tracker: %r: %s' % (name, e))
/common/system/anaconda/envs/python38/lib/python3.8/multiprocessing/resource_tracker.py:229: UserWarning: resource_tracker: '/loky-3651192-6fa4zoje': [Errno 2] No such file or directory
  warnings.warn('resource_tracker: %r: %s' % (name, e))
/common/system/anaconda/envs/python38/lib/python3.8/multiprocessing/resource_tracker.py:229: UserWarning: resource_tracker: '/loky-3651192-yjd1q_m2': [Errno 2] No such file or directory
  warnings.warn('resource_tracker: %r: %s' % (name, e))
/common/system/anaconda/envs/python38/lib/python3.8/multiprocessing/resource_tracker.py:229: UserWarning: resource_tracker: '/loky-3651192-t46c9tg5': [Errno 2] No such file or directory
  warnings.warn('resource_tracker: %r: %s' % (name, e))
